Installing dependencies...
Defaulting to user installation because normal site-packages is not writeable
Collecting flet
  Downloading flet-0.28.3-py3-none-any.whl.metadata (3.6 kB)
Collecting pandas
  Downloading pandas-2.3.0-cp310-cp310-manylinux_2_17_x86_64.manylinux2014_x86_64.whl.metadata (91 kB)
Requirement already satisfied: httpx in /usr/local/lib/python3.10/dist-packages (from flet) (0.28.1)
Requirement already satisfied: oauthlib<4.0.0,>=3.2.2 in /usr/lib/python3/dist-packages (from flet) (3.2.2)
Collecting repath<0.10.0,>=0.9.0 (from flet)
  Downloading repath-0.9.0-py3-none-any.whl.metadata (899 bytes)
Requirement already satisfied: six>=1.9.0 in /usr/lib/python3/dist-packages (from repath<0.10.0,>=0.9.0->flet) (1.16.0)
Collecting numpy>=1.22.4 (from pandas)
  Downloading numpy-2.2.6-cp310-cp310-manylinux_2_17_x86_64.manylinux2014_x86_64.whl.metadata (62 kB)
Requirement already satisfied: python-dateutil>=2.8.2 in /home/jules/.local/lib/python3.10/site-packages (from pandas) (2.9.0.post0)
Collecting pytz>=2020.1 (from pandas)
  Downloading pytz-2025.2-py2.py3-none-any.whl.metadata (22 kB)
Collecting tzdata>=2022.7 (from pandas)
  Downloading tzdata-2025.2-py2.py3-none-any.whl.metadata (1.4 kB)
Requirement already satisfied: anyio in /usr/local/lib/python3.10/dist-packages (from httpx->flet) (4.9.0)
Requirement already satisfied: certifi in /usr/local/lib/python3.10/dist-packages (from httpx->flet) (2025.4.26)
Requirement already satisfied: httpcore==1.* in /usr/local/lib/python3.10/dist-packages (from httpx->flet) (1.0.9)
Requirement already satisfied: idna in /usr/local/lib/python3.10/dist-packages (from httpx->flet) (3.10)
Requirement already satisfied: h11>=0.16 in /usr/local/lib/python3.10/dist-packages (from httpcore==1.*->httpx->flet) (0.16.0)
Requirement already satisfied: exceptiongroup>=1.0.2 in /usr/local/lib/python3.10/dist-packages (from anyio->httpx->flet) (1.2.2)
Requirement already satisfied: sniffio>=1.1 in /usr/local/lib/python3.10/dist-packages (from anyio->httpx->flet) (1.3.1)
Requirement already satisfied: typing_extensions>=4.5 in /usr/local/lib/python3.10/dist-packages (from anyio->httpx->flet) (4.13.2)
Downloading flet-0.28.3-py3-none-any.whl (463 kB)
Downloading repath-0.9.0-py3-none-any.whl (4.7 kB)
Downloading pandas-2.3.0-cp310-cp310-manylinux_2_17_x86_64.manylinux2014_x86_64.whl (12.3 MB)
   ━━━━━━━━━━━━━━━━━━━━━━━━━━━━━━━━━━━━━━━━ 12.3/12.3 MB 24.9 MB/s eta 0:00:00
Downloading numpy-2.2.6-cp310-cp310-manylinux_2_17_x86_64.manylinux2014_x86_64.whl (16.8 MB)
   ━━━━━━━━━━━━━━━━━━━━━━━━━━━━━━━━━━━━━━━━ 16.8/16.8 MB 31.4 MB/s eta 0:00:00
Downloading pytz-2025.2-py2.py3-none-any.whl (509 kB)
Downloading tzdata-2025.2-py2.py3-none-any.whl (347 kB)
Installing collected packages: pytz, tzdata, repath, numpy, pandas, flet
  WARNING: The scripts f2py and numpy-config are installed in '/home/swebot/.local/bin' which is not on PATH.
  Consider adding this directory to PATH or, if you prefer to suppress this warning, use --no-warn-script-location.
  WARNING: The script flet is installed in '/home/swebot/.local/bin' which is not on PATH.
  Consider adding this directory to PATH or, if you prefer to suppress this warning, use --no-warn-script-location.

Successfully installed flet-0.28.3 numpy-2.2.6 pandas-2.3.0 pytz-2025.2 repath-0.9.0 tzdata-2025.2
Dependencies installed successfully.
============================= test session starts ==============================
platform linux -- Python 3.10.17, pytest-8.3.5, pluggy-1.5.0
rootdir: /app
plugins: anyio-4.9.0, cov-6.1.1, json-report-1.5.0, metadata-3.1.1
collected 55 items / 3 errors

==================================== ERRORS ====================================
_____________ ERROR collecting reporter/tests/test_book_closing.py _____________
ImportError while importing test module '/app/reporter/tests/test_book_closing.py'.
Hint: make sure your test modules/packages have valid Python names.
Traceback:
/usr/lib/python3.10/importlib/__init__.py:126: in import_module
    return _bootstrap._gcd_import(name[level:], package, level)
reporter/tests/test_book_closing.py:5: in <module>
    from reporter.gui import GuiController
reporter/gui.py:7: in <module>
    from openpyxl.styles import Font, Border, Side, Alignment, PatternFill
E   ModuleNotFoundError: No module named 'openpyxl'
______________ ERROR collecting reporter/tests/test_gui_flows.py _______________
ImportError while importing test module '/app/reporter/tests/test_gui_flows.py'.
Hint: make sure your test modules/packages have valid Python names.
Traceback:
/usr/lib/python3.10/importlib/__init__.py:126: in import_module
    return _bootstrap._gcd_import(name[level:], package, level)
reporter/tests/test_gui_flows.py:70: in <module>
    from reporter.gui import GuiController
reporter/gui.py:7: in <module>
    from openpyxl.styles import Font, Border, Side, Alignment, PatternFill
E   ModuleNotFoundError: No module named 'openpyxl'
_________________ ERROR collecting reporter/tests/test_main.py _________________
ImportError while importing test module '/app/reporter/tests/test_main.py'.
Hint: make sure your test modules/packages have valid Python names.
Traceback:
reporter/tests/test_main.py:14: in <module>
    from reporter.main import handle_database_migration
reporter/main.py:12: in <module>
    from reporter.gui import main as start_flet_gui # Import main from the new gui.py
reporter/gui.py:7: in <module>
    from openpyxl.styles import Font, Border, Side, Alignment, PatternFill
E   ModuleNotFoundError: No module named 'openpyxl'

During handling of the above exception, another exception occurred:
/usr/lib/python3.10/importlib/__init__.py:126: in import_module
    return _bootstrap._gcd_import(name[level:], package, level)
reporter/tests/test_main.py:18: in <module>
    raise ImportError(f"Could not import handle_database_migration from reporter.main. Error: {e}. Check sys.path and reporter/main.py.")
E   ImportError: Could not import handle_database_migration from reporter.main. Error: No module named 'openpyxl'. Check sys.path and reporter/main.py.
=========================== short test summary info ============================
ERROR reporter/tests/test_book_closing.py
ERROR reporter/tests/test_gui_flows.py
ERROR reporter/tests/test_main.py
!!!!!!!!!!!!!!!!!!! Interrupted: 3 errors during collection !!!!!!!!!!!!!!!!!!!!
============================== 3 errors in 6.68s ===============================
