--- Starting Validation: Wed Jun 11 05:09:20 UTC 2025 ---
Deleting old test logs...

--- Running Automated Tests ---
============================= test session starts ==============================
platform linux -- Python 3.10.17, pytest-8.3.5, pluggy-1.5.0
rootdir: /app
plugins: anyio-4.9.0, cov-6.1.1, json-report-1.5.0, metadata-3.1.1
collected 68 items / 1 error

==================================== ERRORS ====================================
_____________ ERROR collecting reporter/tests/test_migrate_data.py _____________
/usr/local/lib/python3.10/dist-packages/_pytest/python.py:493: in importtestmodule
    mod = import_path(
/usr/local/lib/python3.10/dist-packages/_pytest/pathlib.py:587: in import_path
    importlib.import_module(module_name)
/usr/lib/python3.10/importlib/__init__.py:126: in import_module
    return _bootstrap._gcd_import(name[level:], package, level)
<frozen importlib._bootstrap>:1050: in _gcd_import
    ???
<frozen importlib._bootstrap>:1027: in _find_and_load
    ???
<frozen importlib._bootstrap>:1006: in _find_and_load_unlocked
    ???
<frozen importlib._bootstrap>:688: in _load_unlocked
    ???
/usr/local/lib/python3.10/dist-packages/_pytest/assertion/rewrite.py:185: in exec_module
    exec(co, module.__dict__)
reporter/tests/test_migrate_data.py:6: in <module>
    from reporter.migrate_data import process_gc_data
E     File "/app/reporter/migrate_data.py", line 170
E       except (ValueError, KeyError) as e:
E       ^^^^^^
E   SyntaxError: invalid syntax
=========================== short test summary info ============================
ERROR reporter/tests/test_migrate_data.py
!!!!!!!!!!!!!!!!!!!! Interrupted: 1 error during collection !!!!!!!!!!!!!!!!!!!!
=============================== 1 error in 6.25s ===============================

--- Pytest finished with exit code: 2 ---

--- Checking if application launches ---
Application launched successfully.

--- Validation Complete ---
